Workbook

Sheet scenarios
A1: id | B1: lc_202626 | C1: lc_20266 | D1: lc_202628 | E1: lc_20268 | F1: lc_20269 | G1: lc_2020 | H1: lc_20226 | I1: lc_2022 | J1: lc_20226 | K1: lc_2024 | L1: driver | M1: tcl_year | N1: oil_palm | O1: sdpt_tree_crop | P1: sdpt_planted_forest | Q1: gmw_mangrove | R1: gpw_cultiv_grass
A2: 1 | B2: 26 | C2: 26 | D2: 26 | E2: 26 | F2: 26 | G2: 26 | H2: 26 | I2: 26 | J2: 26 | K2: 26 | N2: TRUE
A3: 2 | B3: 26 | C3: 26 | D3: 26 | E3: 26 | F3: 26 | G3: 26 | H3: 26 | I3: 26 | J3: 26 | K3: 26 | O3: TRUE
A4: 3 | B4: 26 | C4: 26 | D4: 26 | E4: 26 | F4: 26 | G4: 26 | H4: 26 | I4: 26 | J4: 26 | K4: 26 | P4: TRUE | Q4: TRUE
A5: 4 | B5: 26 | C5: 26 | D5: 26 | E5: 26 | F5: 26 | G5: 26 | H5: 26 | I5: 26 | J5: 26 | K5: 26 | L5: 1 | M5: 2015
A6: 5 | B6: 26 | C6: 26 | D6: 26 | E6: 26 | F6: 26 | G6: 26 | H6: 26 | I6: 26 | J6: 26 | K6: 26 | L6: 1 | M6: 2015 | R6: TRUE
A7: 6 | B7: 26 | C7: 26 | D7: 26 | E7: 26 | F7: 26 | G7: 26 | H7: 26 | I7: 26 | J7: 26 | K7: 26 | L7: 1 | M7: 2020
A8: 7 | B8: 26 | C8: 26 | D8: 26 | E8: 26 | F8: 26 | G8: 26 | H8: 26 | I8: 26 | J8: 26 | K8: 26 | L8: 1 | M8: 2020 | R8: TRUE
A9: 8 | B9: 26 | C9: 26 | D9: 26 | E9: 26 | F9: 26 | G9: 26 | H9: 26 | I9: 26 | J9: 26 | K9: 26 | L9: 3 | M9: 2015
A10: 9 | B10: 26 | C10: 26 | D10: 26 | E10: 26 | F10: 26 | G10: 26 | H10: 26 | I10: 26 | J10: 26 | K10: 26 | L10: 4 | M10: 2015
A11: 10 | B11: 26 | C11: 26 | D11: 26 | E11: 26 | F11: 26 | G11: 26 | H11: 26 | I11: 26 | J11: 26 | K11: 26 | L11: 5 | M11: 2015
A12: 11 | B12: 26 | C12: 26 | D12: 26 | E12: 26 | F12: 26 | G12: 26 | H12: 26 | I12: 26 | J12: 26 | K12: 26 | L12: 7 | M12: 2015
A13: 12 | B13: 26 | C13: 26 | D13: 26 | E13: 26 | F13: 26 | G13: 26 | H13: 26 | I13: 26 | J13: 26 | K13: 26 | L13: 3 | M13: 2020
A14: 13 | B14: 26 | C14: 26 | D14: 26 | E14: 26 | F14: 26 | G14: 26 | H14: 26 | I14: 26 | J14: 26 | K14: 26 | L14: 4 | M14: 2020
A15: 14 | B15: 26 | C15: 26 | D15: 26 | E15: 26 | F15: 26 | G15: 26 | H15: 26 | I15: 26 | J15: 26 | K15: 26 | L15: 5 | M15: 2020
A16: 15 | B16: 26 | C16: 26 | D16: 26 | E16: 26 | F16: 26 | G16: 26 | H16: 26 | I16: 26 | J16: 26 | K16: 26 | L16: 7 | M16: 2020
A17: 16 | B17: 28 | C17: 28 | D17: 28 | E17: 28 | F17: 28 | G17: 28 | H17: 28 | I17: 28 | J17: 28 | K17: 28
A18: 17 | B18: 28 | C18: 28 | D18: 28 | E18: 28 | F18: 28 | G18: 28 | H18: 28 | I18: 28 | J18: 28 | K18: 28 | M18: 2015 | N18: TRUE
A19: 18 | B19: 28 | C19: 28 | D19: 28 | E19: 28 | F19: 28 | G19: 28 | H19: 28 | I19: 28 | J19: 28 | K19: 28 | M19: 2015 | O19: TRUE
A20: 19 | B20: 28 | C20: 28 | D20: 28 | E20: 28 | F20: 28 | G20: 28 | H20: 28 | I20: 28 | J20: 28 | K20: 28 | M20: 2020 | N20: TRUE
A21: 20 | B21: 28 | C21: 28 | D21: 28 | E21: 28 | F21: 28 | G21: 28 | H21: 28 | I21: 28 | J21: 28 | K21: 28 | M21: 2020 | O21: TRUE
A22: 21 | B22: 26 | C22: 26 | D22: 26 | E22: 26 | F22: 26 | G22: 26 | H22: 26 | I22: 26 | J22: 26 | K22: 26
A23: 22 | B23: 28 | C23: 28 | D23: 28 | E23: 28 | F23: 28 | G23: 28 | H23: 28 | I23: 26 | J23: 26 | K23: 26
A24: 23 | B24: 28 | C24: 28 | D24: 28 | E24: 28 | F24: 28 | G24: 28 | H24: 28 | I24: 26 | J24: 26 | K24: 26 | L24: 3 | M24: 2021
A25: 24 | B25: 28 | C25: 28 | D25: 28 | E25: 28 | F25: 28 | G25: 28 | H25: 28 | I25: 244 | J25: 244 | K25: 244
A26: 25 | B26: 28 | C26: 28 | D26: 28 | E26: 28 | F26: 28 | G26: 28 | H26: 28 | I26: 244 | J26: 244 | K26: 244 | L26: 3 | M26: 2021
A27: 26 | B27: 28 | C27: 28 | D27: 28 | E27: 26 | F27: 28 | G27: 28 | H27: 28 | I27: 26 | J27: 26 | K27: 26

Sheet scenarios_switch
B1: 2 | C1: 3 | D1: 4 | E1: 5 | F1: 6 | G1: 7 | H1: 8 | I1: 9 | J1: 10 | K1: 11 | L1: 12 | M1: 13 | N1: 14 | O1: 15 | P1: 16 | Q1: 17 | R1: 18 | S1: 19 | T1: 20
A2: id | B2: lc_2015 | C2: lc_2016 | D2: lc_2017 | E2: lc_2018 | F2: lc_2019 | G2: lc_2020 | H2: lc_2021 | I2: lc_2022 | J2: lc_2023 | K2: lc_2024 | L2: driver | M2: tcl_year | N2: oil_palm | O2: sdpt_tree_crop | P2: sdpt_planted_forest | Q2: gmw_mangrove | R2: gpw_cultiv_grass | T2: Expected result:
A3: 1 | B3: {=_xlfn.LET(_xlpm.x, VLOOKUP($A3, scenarios!$A$2:$K$109, B$1, 0), _xlfn.IFS( _xlpm.x=250, "built up", _xlpm.x=244, "cropland", OR(AND(_xlpm.x>=27,_xlpm.x<=48), AND(_xlpm.x>=127,_xlpm.x<=148)), "tall veg", OR(AND(_xlpm.x>=5,_xlpm.x<=26), AND(_xlpm.x>=105,_xlpm.x<=126)), "short veg", AND(_xlpm.x>=200,_xlpm.x<=204), "wetland", OR(AND(_xlpm.x>=0,_xlpm.x<=4), AND(_xlpm.x>=100,_xlpm.x<=104)), "bare", AND(_xlpm.x>=205,_xlpm.x<=207), "water", _xlpm.x=241, "snow/ice" ) )} -> short veg | C3: {=_xlfn.LET(_xlpm.x, VLOOKUP($A3, scenarios!$A$2:$K$109, C$1, 0), _xlfn.IFS( _xlpm.x=250, "built up", _xlpm.x=244, "cropland", OR(AND(_xlpm.x>=27,_xlpm.x<=48), AND(_xlpm.x>=127,_xlpm.x<=148)), "tall veg", OR(AND(_xlpm.x>=5,_xlpm.x<=26), AND(_xlpm.x>=105,_xlpm.x<=126)), "short veg", AND(_xlpm.x>=200,_xlpm.x<=204), "wetland", OR(AND(_xlpm.x>=0,_xlpm.x<=4), AND(_xlpm.x>=100,_xlpm.x<=104)), "bare", AND(_xlpm.x>=205,_xlpm.x<=207), "water", _xlpm.x=241, "snow/ice" ) )} -> short veg | D3: {=_xlfn.LET(_xlpm.x, VLOOKUP($A3, scenarios!$A$2:$K$109, D$1, 0), _xlfn.IFS( _xlpm.x=250, "built up", _xlpm.x=244, "cropland", OR(AND(_xlpm.x>=27,_xlpm.x<=48), AND(_xlpm.x>=127,_xlpm.x<=148)), "tall veg", OR(AND(_xlpm.x>=5,_xlpm.x<=26), AND(_xlpm.x>=105,_xlpm.x<=126)), "short veg", AND(_xlpm.x>=200,_xlpm.x<=204), "wetland", OR(AND(_xlpm.x>=0,_xlpm.x<=4), AND(_xlpm.x>=100,_xlpm.x<=104)), "bare", AND(_xlpm.x>=205,_xlpm.x<=207), "water", _xlpm.x=241, "snow/ice" ) )} -> short veg | E3: {=_xlfn.LET(_xlpm.x, VLOOKUP($A3, scenarios!$A$2:$K$109, E$1, 0), _xlfn.IFS( _xlpm.x=250, "built up", _xlpm.x=244, "cropland", OR(AND(_xlpm.x>=27,_xlpm.x<=48), AND(_xlpm.x>=127,_xlpm.x<=148)), "tall veg", OR(AND(_xlpm.x>=5,_xlpm.x<=26), AND(_xlpm.x>=105,_xlpm.x<=126)), "short veg", AND(_xlpm.x>=200,_xlpm.x<=204), "wetland", OR(AND(_xlpm.x>=0,_xlpm.x<=4), AND(_xlpm.x>=100,_xlpm.x<=104)), "bare", AND(_xlpm.x>=205,_xlpm.x<=207), "water", _xlpm.x=241, "snow/ice" ) )} -> short veg | F3: {=_xlfn.LET(_xlpm.x, VLOOKUP($A3, scenarios!$A$2:$K$109, F$1, 0), _xlfn.IFS( _xlpm.x=250, "built up", _xlpm.x=244, "cropland", OR(AND(_xlpm.x>=27,_xlpm.x<=48), AND(_xlpm.x>=127,_xlpm.x<=148)), "tall veg", OR(AND(_xlpm.x>=5,_xlpm.x<=26), AND(_xlpm.x>=105,_xlpm.x<=126)), "short veg", AND(_xlpm.x>=200,_xlpm.x<=204), "wetland", OR(AND(_xlpm.x>=0,_xlpm.x<=4), AND(_xlpm.x>=100,_xlpm.x<=104)), "bare", AND(_xlpm.x>=205,_xlpm.x<=207), "water", _xlpm.x=241, "snow/ice" ) )} -> short veg | G3: {=_xlfn.LET(_xlpm.x, VLOOKUP($A3, scenarios!$A$2:$K$109, G$1, 0), _xlfn.IFS( _xlpm.x=250, "built up", _xlpm.x=244, "cropland", OR(AND(_xlpm.x>=27,_xlpm.x<=48), AND(_xlpm.x>=127,_xlpm.x<=148)), "tall veg", OR(AND(_xlpm.x>=5,_xlpm.x<=26), AND(_xlpm.x>=105,_xlpm.x<=126)), "short veg", AND(_xlpm.x>=200,_xlpm.x<=204), "wetland", OR(AND(_xlpm.x>=0,_xlpm.x<=4), AND(_xlpm.x>=100,_xlpm.x<=104)), "bare", AND(_xlpm.x>=205,_xlpm.x<=207), "water", _xlpm.x=241, "snow/ice" ) )} -> short veg | H3: {=_xlfn.LET(_xlpm.x, VLOOKUP($A3, scenarios!$A$2:$K$109, H$1, 0), _xlfn.IFS( _xlpm.x=250, "built up", _xlpm.x=244, "cropland", OR(AND(_xlpm.x>=27,_xlpm.x<=48), AND(_xlpm.x>=127,_xlpm.x<=148)), "tall veg", OR(AND(_xlpm.x>=5,_xlpm.x<=26), AND(_xlpm.x>=105,_xlpm.x<=126)), "short veg", AND(_xlpm.x>=200,_xlpm.x<=204), "wetland", OR(AND(_xlpm.x>=0,_xlpm.x<=4), AND(_xlpm.x>=100,_xlpm.x<=104)), "bare", AND(_xlpm.x>=205,_xlpm.x<=207), "water", _xlpm.x=241, "snow/ice" ) )} -> short veg | I3: {=_xlfn.LET(_xlpm.x, VLOOKUP($A3, scenarios!$A$2:$K$109, I$1, 0), _xlfn.IFS( _xlpm.x=250, "built up", _xlpm.x=244, "cropland", OR(AND(_xlpm.x>=27,_xlpm.x<=48), AND(_xlpm.x>=127,_xlpm.x<=148)), "tall veg", OR(AND(_xlpm.x>=5,_xlpm.x<=26), AND(_xlpm.x>=105,_xlpm.x<=126)), "short veg", AND(_xlpm.x>=200,_xlpm.x<=204), "wetland", OR(AND(_xlpm.x>=0,_xlpm.x<=4), AND(_xlpm.x>=100,_xlpm.x<=104)), "bare", AND(_xlpm.x>=205,_xlpm.x<=207), "water", _xlpm.x=241, "snow/ice" ) )} -> short veg | ... K3: {=_xlfn.LET(_xlpm.x, VLOOKUP($A3, scenarios!$A$2:$K$109, K$1, 0), _xlfn.IFS( _xlpm.x=250, "built up", _xlpm.x=244, "cropland", OR(AND(_xlpm.x>=27,_xlpm.x<=48), AND(_xlpm.x>=127,_xlpm.x<=148)), "tall veg", OR(AND(_xlpm.x>=5,_xlpm.x<=26), AND(_xlpm.x>=105,_xlpm.x<=126)), "short veg", AND(_xlpm.x>=200,_xlpm.x<=204), "wetland", OR(AND(_xlpm.x>=0,_xlpm.x<=4), AND(_xlpm.x>=100,_xlpm.x<=104)), "bare", AND(_xlpm.x>=205,_xlpm.x<=207), "water", _xlpm.x=241, "snow/ice" ) )} -> short veg | L3: {=IFERROR(_xlfn.SWITCH(VLOOKUP($A3, scenarios!$A$2:$P$109, L$1, 0), 1, "Permanent agriculture", 2, "Hard commodities", 3, "Shifting cultivation", 4, "Logging", 5, "Wildfire", 6, "Settlements & infrastructure", 7, "Other natural disturbances"), "")} | M3: =_xlfn.LET(_xlpm.x, scenarios!M2, IF(OR(ISERROR(_xlpm.x), _xlpm.x=0), "", _xlpm.x)) | N3: =_xlfn.LET(_xlpm.x, scenarios!N2, IF(OR(ISERROR(_xlpm.x), _xlpm.x=0), "", _xlpm.x)) -> TRUE | O3: =_xlfn.LET(_xlpm.x, scenarios!O2, IF(OR(ISERROR(_xlpm.x), _xlpm.x=0), "", _xlpm.x)) | P3: =_xlfn.LET(_xlpm.x, scenarios!P2, IF(OR(ISERROR(_xlpm.x), _xlpm.x=0), "", _xlpm.x)) | Q3: =_xlfn.LET(_xlpm.x, scenarios!Q2, IF(OR(ISERROR(_xlpm.x), _xlpm.x=0), "", _xlpm.x)) | R3: =_xlfn.LET(_xlpm.x, scenarios!R2, IF(OR(ISERROR(_xlpm.x), _xlpm.x=0), "", _xlpm.x))
A4: 2 | B4: {=_xlfn.LET(_xlpm.x, VLOOKUP($A4, scenarios!$A$2:$K$109, B$1, 0), _xlfn.IFS( _xlpm.x=250, "built up", _xlpm.x=244, "cropland", OR(AND(_xlpm.x>=27,_xlpm.x<=48), AND(_xlpm.x>=127,_xlpm.x<=148)), "tall veg", OR(AND(_xlpm.x>=5,_xlpm.x<=26), AND(_xlpm.x>=105,_xlpm.x<=126)), "short veg", AND(_xlpm.x>=200,_xlpm.x<=204), "wetland", OR(AND(_xlpm.x>=0,_xlpm.x<=4), AND(_xlpm.x>=100,_xlpm.x<=104)), "bare", AND(_xlpm.x>=205,_xlpm.x<=207), "water", _xlpm.x=241, "snow/ice" ) )} -> short veg | C4: {=_xlfn.LET(_xlpm.x, VLOOKUP($A4, scenarios!$A$2:$K$109, C$1, 0), _xlfn.IFS( _xlpm.x=250, "built up", _xlpm.x=244, "cropland", OR(AND(_xlpm.x>=27,_xlpm.x<=48), AND(_xlpm.x>=127,_xlpm.x<=148)), "tall veg", OR(AND(_xlpm.x>=5,_xlpm.x<=26), AND(_xlpm.x>=105,_xlpm.x<=126)), "short veg", AND(_xlpm.x>=200,_xlpm.x<=204), "wetland", OR(AND(_xlpm.x>=0,_xlpm.x<=4), AND(_xlpm.x>=100,_xlpm.x<=104)), "bare", AND(_xlpm.x>=205,_xlpm.x<=207), "water", _xlpm.x=241, "snow/ice" ) )} -> short veg | D4: {=_xlfn.LET(_xlpm.x, VLOOKUP($A4, scenarios!$A$2:$K$109, D$1, 0), _xlfn.IFS( _xlpm.x=250, "built up", _xlpm.x=244, "cropland", OR(AND(_xlpm.x>=27,_xlpm.x<=48), AND(_xlpm.x>=127,_xlpm.x<=148)), "tall veg", OR(AND(_xlpm.x>=5,_xlpm.x<=26), AND(_xlpm.x>=105,_xlpm.x<=126)), "short veg", AND(_xlpm.x>=200,_xlpm.x<=204), "wetland", OR(AND(_xlpm.x>=0,_xlpm.x<=4), AND(_xlpm.x>=100,_xlpm.x<=104)), "bare", AND(_xlpm.x>=205,_xlpm.x<=207), "water", _xlpm.x=241, "snow/ice" ) )} -> short veg | E4: {=_xlfn.LET(_xlpm.x, VLOOKUP($A4, scenarios!$A$2:$K$109, E$1, 0), _xlfn.IFS( _xlpm.x=250, "built up", _xlpm.x=244, "cropland", OR(AND(_xlpm.x>=27,_xlpm.x<=48), AND(_xlpm.x>=127,_xlpm.x<=148)), "tall veg", OR(AND(_xlpm.x>=5,_xlpm.x<=26), AND(_xlpm.x>=105,_xlpm.x<=126)), "short veg", AND(_xlpm.x>=200,_xlpm.x<=204), "wetland", OR(AND(_xlpm.x>=0,_xlpm.x<=4), AND(_xlpm.x>=100,_xlpm.x<=104)), "bare", AND(_xlpm.x>=205,_xlpm.x<=207), "water", _xlpm.x=241, "snow/ice" ) )} -> short veg | F4: {=_xlfn.LET(_xlpm.x, VLOOKUP($A4, scenarios!$A$2:$K$109, F$1, 0), _xlfn.IFS( _xlpm.x=250, "built up", _xlpm.x=244, "cropland", OR(AND(_xlpm.x>=27,_xlpm.x<=48), AND(_xlpm.x>=127,_xlpm.x<=148)), "tall veg", OR(AND(_xlpm.x>=5,_xlpm.x<=26), AND(_xlpm.x>=105,_xlpm.x<=126)), "short veg", AND(_xlpm.x>=200,_xlpm.x<=204), "wetland", OR(AND(_xlpm.x>=0,_xlpm.x<=4), AND(_xlpm.x>=100,_xlpm.x<=104)), "bare", AND(_xlpm.x>=205,_xlpm.x<=207), "water", _xlpm.x=241, "snow/ice" ) )} -> short veg | G4: {=_xlfn.LET(_xlpm.x, VLOOKUP($A4, scenarios!$A$2:$K$109, G$1, 0), _xlfn.IFS( _xlpm.x=250, "built up", _xlpm.x=244, "cropland", OR(AND(_xlpm.x>=27,_xlpm.x<=48), AND(_xlpm.x>=127,_xlpm.x<=148)), "tall veg", OR(AND(_xlpm.x>=5,_xlpm.x<=26), AND(_xlpm.x>=105,_xlpm.x<=126)), "short veg", AND(_xlpm.x>=200,_xlpm.x<=204), "wetland", OR(AND(_xlpm.x>=0,_xlpm.x<=4), AND(_xlpm.x>=100,_xlpm.x<=104)), "bare", AND(_xlpm.x>=205,_xlpm.x<=207), "water", _xlpm.x=241, "snow/ice" ) )} -> short veg | H4: {=_xlfn.LET(_xlpm.x, VLOOKUP($A4, scenarios!$A$2:$K$109, H$1, 0), _xlfn.IFS( _xlpm.x=250, "built up", _xlpm.x=244, "cropland", OR(AND(_xlpm.x>=27,_xlpm.x<=48), AND(_xlpm.x>=127,_xlpm.x<=148)), "tall veg", OR(AND(_xlpm.x>=5,_xlpm.x<=26), AND(_xlpm.x>=105,_xlpm.x<=126)), "short veg", AND(_xlpm.x>=200,_xlpm.x<=204), "wetland", OR(AND(_xlpm.x>=0,_xlpm.x<=4), AND(_xlpm.x>=100,_xlpm.x<=104)), "bare", AND(_xlpm.x>=205,_xlpm.x<=207), "water", _xlpm.x=241, "snow/ice" ) )} -> short veg | I4: {=_xlfn.LET(_xlpm.x, VLOOKUP($A4, scenarios!$A$2:$K$109, I$1, 0), _xlfn.IFS( _xlpm.x=250, "built up", _xlpm.x=244, "cropland", OR(AND(_xlpm.x>=27,_xlpm.x<=48), AND(_xlpm.x>=127,_xlpm.x<=148)), "tall veg", OR(AND(_xlpm.x>=5,_xlpm.x<=26), AND(_xlpm.x>=105,_xlpm.x<=126)), "short veg", AND(_xlpm.x>=200,_xlpm.x<=204), "wetland", OR(AND(_xlpm.x>=0,_xlpm.x<=4), AND(_xlpm.x>=100,_xlpm.x<=104)), "bare", AND(_xlpm.x>=205,_xlpm.x<=207), "water", _xlpm.x=241, "snow/ice" ) )} -> short veg | ... K4: {=_xlfn.LET(_xlpm.x, VLOOKUP($A4, scenarios!$A$2:$K$109, K$1, 0), _xlfn.IFS( _xlpm.x=250, "built up", _xlpm.x=244, "cropland", OR(AND(_xlpm.x>=27,_xlpm.x<=48), AND(_xlpm.x>=127,_xlpm.x<=148)), "tall veg", OR(AND(_xlpm.x>=5,_xlpm.x<=26), AND(_xlpm.x>=105,_xlpm.x<=126)), "short veg", AND(_xlpm.x>=200,_xlpm.x<=204), "wetland", OR(AND(_xlpm.x>=0,_xlpm.x<=4), AND(_xlpm.x>=100,_xlpm.x<=104)), "bare", AND(_xlpm.x>=205,_xlpm.x<=207), "water", _xlpm.x=241, "snow/ice" ) )} -> short veg | L4: {=IFERROR(_xlfn.SWITCH(VLOOKUP($A4, scenarios!$A$2:$P$109, L$1, 0), 1, "Permanent agriculture", 2, "Hard commodities", 3, "Shifting cultivation", 4, "Logging", 5, "Wildfire", 6, "Settlements & infrastructure", 7, "Other natural disturbances"), "")} | M4: =_xlfn.LET(_xlpm.x, scenarios!M3, IF(OR(ISERROR(_xlpm.x), _xlpm.x=0), "", _xlpm.x)) | N4: =_xlfn.LET(_xlpm.x, scenarios!N3, IF(OR(ISERROR(_xlpm.x), _xlpm.x=0), "", _xlpm.x)) | O4: =_xlfn.LET(_xlpm.x, scenarios!O3, IF(OR(ISERROR(_xlpm.x), _xlpm.x=0), "", _xlpm.x)) -> TRUE | P4: =_xlfn.LET(_xlpm.x, scenarios!P3, IF(OR(ISERROR(_xlpm.x), _xlpm.x=0), "", _xlpm.x)) | Q4: =_xlfn.LET(_xlpm.x, scenarios!Q3, IF(OR(ISERROR(_xlpm.x), _xlpm.x=0), "", _xlpm.x)) | R4: =_xlfn.LET(_xlpm.x, scenarios!R3, IF(OR(ISERROR(_xlpm.x), _xlpm.x=0), "", _xlpm.x))
A5: 3 | B5: {=_xlfn.LET(_xlpm.x, VLOOKUP($A5, scenarios!$A$2:$K$109, B$1, 0), _xlfn.IFS( _xlpm.x=250, "built up", _xlpm.x=244, "cropland", OR(AND(_xlpm.x>=27,_xlpm.x<=48), AND(_xlpm.x>=127,_xlpm.x<=148)), "tall veg", OR(AND(_xlpm.x>=5,_xlpm.x<=26), AND(_xlpm.x>=105,_xlpm.x<=126)), "short veg", AND(_xlpm.x>=200,_xlpm.x<=204), "wetland", OR(AND(_xlpm.x>=0,_xlpm.x<=4), AND(_xlpm.x>=100,_xlpm.x<=104)), "bare", AND(_xlpm.x>=205,_xlpm.x<=207), "water", _xlpm.x=241, "snow/ice" ) )} -> short veg | C5: {=_xlfn.LET(_xlpm.x, VLOOKUP($A5, scenarios!$A$2:$K$109, C$1, 0), _xlfn.IFS( _xlpm.x=250, "built up", _xlpm.x=244, "cropland", OR(AND(_xlpm.x>=27,_xlpm.x<=48), AND(_xlpm.x>=127,_xlpm.x<=148)), "tall veg", OR(AND(_xlpm.x>=5,_xlpm.x<=26), AND(_xlpm.x>=105,_xlpm.x<=126)), "short veg", AND(_xlpm.x>=200,_xlpm.x<=204), "wetland", OR(AND(_xlpm.x>=0,_xlpm.x<=4), AND(_xlpm.x>=100,_xlpm.x<=104)), "bare", AND(_xlpm.x>=205,_xlpm.x<=207), "water", _xlpm.x=241, "snow/ice" ) )} -> short veg | D5: {=_xlfn.LET(_xlpm.x, VLOOKUP($A5, scenarios!$A$2:$K$109, D$1, 0), _xlfn.IFS( _xlpm.x=250, "built up", _xlpm.x=244, "cropland", OR(AND(_xlpm.x>=27,_xlpm.x<=48), AND(_xlpm.x>=127,_xlpm.x<=148)), "tall veg", OR(AND(_xlpm.x>=5,_xlpm.x<=26), AND(_xlpm.x>=105,_xlpm.x<=126)), "short veg", AND(_xlpm.x>=200,_xlpm.x<=204), "wetland", OR(AND(_xlpm.x>=0,_xlpm.x<=4), AND(_xlpm.x>=100,_xlpm.x<=104)), "bare", AND(_xlpm.x>=205,_xlpm.x<=207), "water", _xlpm.x=241, "snow/ice" ) )} -> short veg | E5: {=_xlfn.LET(_xlpm.x, VLOOKUP($A5, scenarios!$A$2:$K$109, E$1, 0), _xlfn.IFS( _xlpm.x=250, "built up", _xlpm.x=244, "cropland", OR(AND(_xlpm.x>=27,_xlpm.x<=48), AND(_xlpm.x>=127,_xlpm.x<=148)), "tall veg", OR(AND(_xlpm.x>=5,_xlpm.x<=26), AND(_xlpm.x>=105,_xlpm.x<=126)), "short veg", AND(_xlpm.x>=200,_xlpm.x<=204), "wetland", OR(AND(_xlpm.x>=0,_xlpm.x<=4), AND(_xlpm.x>=100,_xlpm.x<=104)), "bare", AND(_xlpm.x>=205,_xlpm.x<=207), "water", _xlpm.x=241, "snow/ice" ) )} -> short veg | F5: {=_xlfn.LET(_xlpm.x, VLOOKUP($A5, scenarios!$A$2:$K$109, F$1, 0), _xlfn.IFS( _xlpm.x=250, "built up", _xlpm.x=244, "cropland", OR(AND(_xlpm.x>=27,_xlpm.x<=48), AND(_xlpm.x>=127,_xlpm.x<=148)), "tall veg", OR(AND(_xlpm.x>=5,_xlpm.x<=26), AND(_xlpm.x>=105,_xlpm.x<=126)), "short veg", AND(_xlpm.x>=200,_xlpm.x<=204), "wetland", OR(AND(_xlpm.x>=0,_xlpm.x<=4), AND(_xlpm.x>=100,_xlpm.x<=104)), "bare", AND(_xlpm.x>=205,_xlpm.x<=207), "water", _xlpm.x=241, "snow/ice" ) )} -> short veg | G5: {=_xlfn.LET(_xlpm.x, VLOOKUP($A5, scenarios!$A$2:$K$109, G$1, 0), _xlfn.IFS( _xlpm.x=250, "built up", _xlpm.x=244, "cropland", OR(AND(_xlpm.x>=27,_xlpm.x<=48), AND(_xlpm.x>=127,_xlpm.x<=148)), "tall veg", OR(AND(_xlpm.x>=5,_xlpm.x<=26), AND(_xlpm.x>=105,_xlpm.x<=126)), "short veg", AND(_xlpm.x>=200,_xlpm.x<=204), "wetland", OR(AND(_xlpm.x>=0,_xlpm.x<=4), AND(_xlpm.x>=100,_xlpm.x<=104)), "bare", AND(_xlpm.x>=205,_xlpm.x<=207), "water", _xlpm.x=241, "snow/ice" ) )} -> short veg | H5: {=_xlfn.LET(_xlpm.x, VLOOKUP($A5, scenarios!$A$2:$K$109, H$1, 0), _xlfn.IFS( _xlpm.x=250, "built up", _xlpm.x=244, "cropland", OR(AND(_xlpm.x>=27,_xlpm.x<=48), AND(_xlpm.x>=127,_xlpm.x<=148)), "tall veg", OR(AND(_xlpm.x>=5,_xlpm.x<=26), AND(_xlpm.x>=105,_xlpm.x<=126)), "short veg", AND(_xlpm.x>=200,_xlpm.x<=204), "wetland", OR(AND(_xlpm.x>=0,_xlpm.x<=4), AND(_xlpm.x>=100,_xlpm.x<=104)), "bare", AND(_xlpm.x>=205,_xlpm.x<=207), "water", _xlpm.x=241, "snow/ice" ) )} -> short veg | I5: {=_xlfn.LET(_xlpm.x, VLOOKUP($A5, scenarios!$A$2:$K$109, I$1, 0), _xlfn.IFS( _xlpm.x=250, "built up", _xlpm.x=244, "cropland", OR(AND(_xlpm.x>=27,_xlpm.x<=48), AND(_xlpm.x>=127,_xlpm.x<=148)), "tall veg", OR(AND(_xlpm.x>=5,_xlpm.x<=26), AND(_xlpm.x>=105,_xlpm.x<=126)), "short veg", AND(_xlpm.x>=200,_xlpm.x<=204), "wetland", OR(AND(_xlpm.x>=0,_xlpm.x<=4), AND(_xlpm.x>=100,_xlpm.x<=104)), "bare", AND(_xlpm.x>=205,_xlpm.x<=207), "water", _xlpm.x=241, "snow/ice" ) )} -> short veg | ... K5: {=_xlfn.LET(_xlpm.x, VLOOKUP($A5, scenarios!$A$2:$K$109, K$1, 0), _xlfn.IFS( _xlpm.x=250, "built up", _xlpm.x=244, "cropland", OR(AND(_xlpm.x>=27,_xlpm.x<=48), AND(_xlpm.x>=127,_xlpm.x<=148)), "tall veg", OR(AND(_xlpm.x>=5,_xlpm.x<=26), AND(_xlpm.x>=105,_xlpm.x<=126)), "short veg", AND(_xlpm.x>=200,_xlpm.x<=204), "wetland", OR(AND(_xlpm.x>=0,_xlpm.x<=4), AND(_xlpm.x>=100,_xlpm.x<=104)), "bare", AND(_xlpm.x>=205,_xlpm.x<=207), "water", _xlpm.x=241, "snow/ice" ) )} -> short veg | L5: {=IFERROR(_xlfn.SWITCH(VLOOKUP($A5, scenarios!$A$2:$P$109, L$1, 0), 1, "Permanent agriculture", 2, "Hard commodities", 3, "Shifting cultivation", 4, "Logging", 5, "Wildfire", 6, "Settlements & infrastructure", 7, "Other natural disturbances"), "")} | M5: =_xlfn.LET(_xlpm.x, scenarios!M4, IF(OR(ISERROR(_xlpm.x), _xlpm.x=0), "", _xlpm.x)) | N5: =_xlfn.LET(_xlpm.x, scenarios!N4, IF(OR(ISERROR(_xlpm.x), _xlpm.x=0), "", _xlpm.x)) | O5: =_xlfn.LET(_xlpm.x, scenarios!O4, IF(OR(ISERROR(_xlpm.x), _xlpm.x=0), "", _xlpm.x)) | P5: =_xlfn.LET(_xlpm.x, scenarios!P4, IF(OR(ISERROR(_xlpm.x), _xlpm.x=0), "", _xlpm.x)) -> TRUE | Q5: =_xlfn.LET(_xlpm.x, scenarios!Q4, IF(OR(ISERROR(_xlpm.x), _xlpm.x=0), "", _xlpm.x)) -> TRUE | R5: =_xlfn.LET(_xlpm.x, scenarios!R4, IF(OR(ISERROR(_xlpm.x), _xlpm.x=0), "", _xlpm.x))
A6: 4 | B6: {=_xlfn.LET(_xlpm.x, VLOOKUP($A6, scenarios!$A$2:$K$109, B$1, 0), _xlfn.IFS( _xlpm.x=250, "built up", _xlpm.x=244, "cropland", OR(AND(_xlpm.x>=27,_xlpm.x<=48), AND(_xlpm.x>=127,_xlpm.x<=148)), "tall veg", OR(AND(_xlpm.x>=5,_xlpm.x<=26), AND(_xlpm.x>=105,_xlpm.x<=126)), "short veg", AND(_xlpm.x>=200,_xlpm.x<=204), "wetland", OR(AND(_xlpm.x>=0,_xlpm.x<=4), AND(_xlpm.x>=100,_xlpm.x<=104)), "bare", AND(_xlpm.x>=205,_xlpm.x<=207), "water", _xlpm.x=241, "snow/ice" ) )} -> short veg | C6: {=_xlfn.LET(_xlpm.x, VLOOKUP($A6, scenarios!$A$2:$K$109, C$1, 0), _xlfn.IFS( _xlpm.x=250, "built up", _xlpm.x=244, "cropland", OR(AND(_xlpm.x>=27,_xlpm.x<=48), AND(_xlpm.x>=127,_xlpm.x<=148)), "tall veg", OR(AND(_xlpm.x>=5,_xlpm.x<=26), AND(_xlpm.x>=105,_xlpm.x<=126)), "short veg", AND(_xlpm.x>=200,_xlpm.x<=204), "wetland", OR(AND(_xlpm.x>=0,_xlpm.x<=4), AND(_xlpm.x>=100,_xlpm.x<=104)), "bare", AND(_xlpm.x>=205,_xlpm.x<=207), "water", _xlpm.x=241, "snow/ice" ) )} -> short veg | D6: {=_xlfn.LET(_xlpm.x, VLOOKUP($A6, scenarios!$A$2:$K$109, D$1, 0), _xlfn.IFS( _xlpm.x=250, "built up", _xlpm.x=244, "cropland", OR(AND(_xlpm.x>=27,_xlpm.x<=48), AND(_xlpm.x>=127,_xlpm.x<=148)), "tall veg", OR(AND(_xlpm.x>=5,_xlpm.x<=26), AND(_xlpm.x>=105,_xlpm.x<=126)), "short veg", AND(_xlpm.x>=200,_xlpm.x<=204), "wetland", OR(AND(_xlpm.x>=0,_xlpm.x<=4), AND(_xlpm.x>=100,_xlpm.x<=104)), "bare", AND(_xlpm.x>=205,_xlpm.x<=207), "water", _xlpm.x=241, "snow/ice" ) )} -> short veg | E6: {=_xlfn.LET(_xlpm.x, VLOOKUP($A6, scenarios!$A$2:$K$109, E$1, 0), _xlfn.IFS( _xlpm.x=250, "built up", _xlpm.x=244, "cropland", OR(AND(_xlpm.x>=27,_xlpm.x<=48), AND(_xlpm.x>=127,_xlpm.x<=148)), "tall veg", OR(AND(_xlpm.x>=5,_xlpm.x<=26), AND(_xlpm.x>=105,_xlpm.x<=126)), "short veg", AND(_xlpm.x>=200,_xlpm.x<=204), "wetland", OR(AND(_xlpm.x>=0,_xlpm.x<=4), AND(_xlpm.x>=100,_xlpm.x<=104)), "bare", AND(_xlpm.x>=205,_xlpm.x<=207), "water", _xlpm.x=241, "snow/ice" ) )} -> short veg | F6: {=_xlfn.LET(_xlpm.x, VLOOKUP($A6, scenarios!$A$2:$K$109, F$1, 0), _xlfn.IFS( _xlpm.x=250, "built up", _xlpm.x=244, "cropland", OR(AND(_xlpm.x>=27,_xlpm.x<=48), AND(_xlpm.x>=127,_xlpm.x<=148)), "tall veg", OR(AND(_xlpm.x>=5,_xlpm.x<=26), AND(_xlpm.x>=105,_xlpm.x<=126)), "short veg", AND(_xlpm.x>=200,_xlpm.x<=204), "wetland", OR(AND(_xlpm.x>=0,_xlpm.x<=4), AND(_xlpm.x>=100,_xlpm.x<=104)), "bare", AND(_xlpm.x>=205,_xlpm.x<=207), "water", _xlpm.x=241, "snow/ice" ) )} -> short veg | G6: {=_xlfn.LET(_xlpm.x, VLOOKUP($A6, scenarios!$A$2:$K$109, G$1, 0), _xlfn.IFS( _xlpm.x=250, "built up", _xlpm.x=244, "cropland", OR(AND(_xlpm.x>=27,_xlpm.x<=48), AND(_xlpm.x>=127,_xlpm.x<=148)), "tall veg", OR(AND(_xlpm.x>=5,_xlpm.x<=26), AND(_xlpm.x>=105,_xlpm.x<=126)), "short veg", AND(_xlpm.x>=200,_xlpm.x<=204), "wetland", OR(AND(_xlpm.x>=0,_xlpm.x<=4), AND(_xlpm.x>=100,_xlpm.x<=104)), "bare", AND(_xlpm.x>=205,_xlpm.x<=207), "water", _xlpm.x=241, "snow/ice" ) )} -> short veg | H6: {=_xlfn.LET(_xlpm.x, VLOOKUP($A6, scenarios!$A$2:$K$109, H$1, 0), _xlfn.IFS( _xlpm.x=250, "built up", _xlpm.x=244, "cropland", OR(AND(_xlpm.x>=27,_xlpm.x<=48), AND(_xlpm.x>=127,_xlpm.x<=148)), "tall veg", OR(AND(_xlpm.x>=5,_xlpm.x<=26), AND(_xlpm.x>=105,_xlpm.x<=126)), "short veg", AND(_xlpm.x>=200,_xlpm.x<=204), "wetland", OR(AND(_xlpm.x>=0,_xlpm.x<=4), AND(_xlpm.x>=100,_xlpm.x<=104)), "bare", AND(_xlpm.x>=205,_xlpm.x<=207), "water", _xlpm.x=241, "snow/ice" ) )} -> short veg | I6: {=_xlfn.LET(_xlpm.x, VLOOKUP($A6, scenarios!$A$2:$K$109, I$1, 0), _xlfn.IFS( _xlpm.x=250, "built up", _xlpm.x=244, "cropland", OR(AND(_xlpm.x>=27,_xlpm.x<=48), AND(_xlpm.x>=127,_xlpm.x<=148)), "tall veg", OR(AND(_xlpm.x>=5,_xlpm.x<=26), AND(_xlpm.x>=105,_xlpm.x<=126)), "short veg", AND(_xlpm.x>=200,_xlpm.x<=204), "wetland", OR(AND(_xlpm.x>=0,_xlpm.x<=4), AND(_xlpm.x>=100,_xlpm.x<=104)), "bare", AND(_xlpm.x>=205,_xlpm.x<=207), "water", _xlpm.x=241, "snow/ice" ) )} -> short veg | ... K6: {=_xlfn.LET(_xlpm.x, VLOOKUP($A6, scenarios!$A$2:$K$109, K$1, 0), _xlfn.IFS( _xlpm.x=250, "built up", _xlpm.x=244, "cropland", OR(AND(_xlpm.x>=27,_xlpm.x<=48), AND(_xlpm.x>=127,_xlpm.x<=148)), "tall veg", OR(AND(_xlpm.x>=5,_xlpm.x<=26), AND(_xlpm.x>=105,_xlpm.x<=126)), "short veg", AND(_xlpm.x>=200,_xlpm.x<=204), "wetland", OR(AND(_xlpm.x>=0,_xlpm.x<=4), AND(_xlpm.x>=100,_xlpm.x<=104)), "bare", AND(_xlpm.x>=205,_xlpm.x<=207), "water", _xlpm.x=241, "snow/ice" ) )} -> short veg | L6: {=IFERROR(_xlfn.SWITCH(VLOOKUP($A6, scenarios!$A$2:$P$109, L$1, 0), 1, "Permanent agriculture", 2, "Hard commodities", 3, "Shifting cultivation", 4, "Logging", 5, "Wildfire", 6, "Settlements & infrastructure", 7, "Other natural disturbances"), "")} -> Permanent agriculture | M6: =_xlfn.LET(_xlpm.x, scenarios!M5, IF(OR(ISERROR(_xlpm.x), _xlpm.x=0), "", _xlpm.x)) -> 2015 | N6: =_xlfn.LET(_xlpm.x, scenarios!N5, IF(OR(ISERROR(_xlpm.x), _xlpm.x=0), "", _xlpm.x)) | O6: =_xlfn.LET(_xlpm.x, scenarios!O5, IF(OR(ISERROR(_xlpm.x), _xlpm.x=0), "", _xlpm.x)) | P6: =_xlfn.LET(_xlpm.x, scenarios!P5, IF(OR(ISERROR(_xlpm.x), _xlpm.x=0), "", _xlpm.x)) | Q6: =_xlfn.LET(_xlpm.x, scenarios!Q5, IF(OR(ISERROR(_xlpm.x), _xlpm.x=0), "", _xlpm.x)) | R6: =_xlfn.LET(_xlpm.x, scenarios!R5, IF(OR(ISERROR(_xlpm.x), _xlpm.x=0), "", _xlpm.x))
A7: 5 | B7: {=_xlfn.LET(_xlpm.x, VLOOKUP($A7, scenarios!$A$2:$K$109, B$1, 0), _xlfn.IFS( _xlpm.x=250, "built up", _xlpm.x=244, "cropland", OR(AND(_xlpm.x>=27,_xlpm.x<=48), AND(_xlpm.x>=127,_xlpm.x<=148)), "tall veg", OR(AND(_xlpm.x>=5,_xlpm.x<=26), AND(_xlpm.x>=105,_xlpm.x<=126)), "short veg", AND(_xlpm.x>=200,_xlpm.x<=204), "wetland", OR(AND(_xlpm.x>=0,_xlpm.x<=4), AND(_xlpm.x>=100,_xlpm.x<=104)), "bare", AND(_xlpm.x>=205,_xlpm.x<=207), "water", _xlpm.x=241, "snow/ice" ) )} -> short veg | C7: {=_xlfn.LET(_xlpm.x, VLOOKUP($A7, scenarios!$A$2:$K$109, C$1, 0), _xlfn.IFS( _xlpm.x=250, "built up", _xlpm.x=244, "cropland", OR(AND(_xlpm.x>=27,_xlpm.x<=48), AND(_xlpm.x>=127,_xlpm.x<=148)), "tall veg", OR(AND(_xlpm.x>=5,_xlpm.x<=26), AND(_xlpm.x>=105,_xlpm.x<=126)), "short veg", AND(_xlpm.x>=200,_xlpm.x<=204), "wetland", OR(AND(_xlpm.x>=0,_xlpm.x<=4), AND(_xlpm.x>=100,_xlpm.x<=104)), "bare", AND(_xlpm.x>=205,_xlpm.x<=207), "water", _xlpm.x=241, "snow/ice" ) )} -> short veg | D7: {=_xlfn.LET(_xlpm.x, VLOOKUP($A7, scenarios!$A$2:$K$109, D$1, 0), _xlfn.IFS( _xlpm.x=250, "built up", _xlpm.x=244, "cropland", OR(AND(_xlpm.x>=27,_xlpm.x<=48), AND(_xlpm.x>=127,_xlpm.x<=148)), "tall veg", OR(AND(_xlpm.x>=5,_xlpm.x<=26), AND(_xlpm.x>=105,_xlpm.x<=126)), "short veg", AND(_xlpm.x>=200,_xlpm.x<=204), "wetland", OR(AND(_xlpm.x>=0,_xlpm.x<=4), AND(_xlpm.x>=100,_xlpm.x<=104)), "bare", AND(_xlpm.x>=205,_xlpm.x<=207), "water", _xlpm.x=241, "snow/ice" ) )} -> short veg | E7: {=_xlfn.LET(_xlpm.x, VLOOKUP($A7, scenarios!$A$2:$K$109, E$1, 0), _xlfn.IFS( _xlpm.x=250, "built up", _xlpm.x=244, "cropland", OR(AND(_xlpm.x>=27,_xlpm.x<=48), AND(_xlpm.x>=127,_xlpm.x<=148)), "tall veg", OR(AND(_xlpm.x>=5,_xlpm.x<=26), AND(_xlpm.x>=105,_xlpm.x<=126)), "short veg", AND(_xlpm.x>=200,_xlpm.x<=204), "wetland", OR(AND(_xlpm.x>=0,_xlpm.x<=4), AND(_xlpm.x>=100,_xlpm.x<=104)), "bare", AND(_xlpm.x>=205,_xlpm.x<=207), "water", _xlpm.x=241, "snow/ice" ) )} -> short veg | F7: {=_xlfn.LET(_xlpm.x, VLOOKUP($A7, scenarios!$A$2:$K$109, F$1, 0), _xlfn.IFS( _xlpm.x=250, "built up", _xlpm.x=244, "cropland", OR(AND(_xlpm.x>=27,_xlpm.x<=48), AND(_xlpm.x>=127,_xlpm.x<=148)), "tall veg", OR(AND(_xlpm.x>=5,_xlpm.x<=26), AND(_xlpm.x>=105,_xlpm.x<=126)), "short veg", AND(_xlpm.x>=200,_xlpm.x<=204), "wetland", OR(AND(_xlpm.x>=0,_xlpm.x<=4), AND(_xlpm.x>=100,_xlpm.x<=104)), "bare", AND(_xlpm.x>=205,_xlpm.x<=207), "water", _xlpm.x=241, "snow/ice" ) )} -> short veg | G7: {=_xlfn.LET(_xlpm.x, VLOOKUP($A7, scenarios!$A$2:$K$109, G$1, 0), _xlfn.IFS( _xlpm.x=250, "built up", _xlpm.x=244, "cropland", OR(AND(_xlpm.x>=27,_xlpm.x<=48), AND(_xlpm.x>=127,_xlpm.x<=148)), "tall veg", OR(AND(_xlpm.x>=5,_xlpm.x<=26), AND(_xlpm.x>=105,_xlpm.x<=126)), "short veg", AND(_xlpm.x>=200,_xlpm.x<=204), "wetland", OR(AND(_xlpm.x>=0,_xlpm.x<=4), AND(_xlpm.x>=100,_xlpm.x<=104)), "bare", AND(_xlpm.x>=205,_xlpm.x<=207), "water", _xlpm.x=241, "snow/ice" ) )} -> short veg | H7: {=_xlfn.LET(_xlpm.x, VLOOKUP($A7, scenarios!$A$2:$K$109, H$1, 0), _xlfn.IFS( _xlpm.x=250, "built up", _xlpm.x=244, "cropland", OR(AND(_xlpm.x>=27,_xlpm.x<=48), AND(_xlpm.x>=127,_xlpm.x<=148)), "tall veg", OR(AND(_xlpm.x>=5,_xlpm.x<=26), AND(_xlpm.x>=105,_xlpm.x<=126)), "short veg", AND(_xlpm.x>=200,_xlpm.x<=204), "wetland", OR(AND(_xlpm.x>=0,_xlpm.x<=4), AND(_xlpm.x>=100,_xlpm.x<=104)), "bare", AND(_xlpm.x>=205,_xlpm.x<=207), "water", _xlpm.x=241, "snow/ice" ) )} -> short veg | I7: {=_xlfn.LET(_xlpm.x, VLOOKUP($A7, scenarios!$A$2:$K$109, I$1, 0), _xlfn.IFS( _xlpm.x=250, "built up", _xlpm.x=244, "cropland", OR(AND(_xlpm.x>=27,_xlpm.x<=48), AND(_xlpm.x>=127,_xlpm.x<=148)), "tall veg", OR(AND(_xlpm.x>=5,_xlpm.x<=26), AND(_xlpm.x>=105,_xlpm.x<=126)), "short veg", AND(_xlpm.x>=200,_xlpm.x<=204), "wetland", OR(AND(_xlpm.x>=0,_xlpm.x<=4), AND(_xlpm.x>=100,_xlpm.x<=104)), "bare", AND(_xlpm.x>=205,_xlpm.x<=207), "water", _xlpm.x=241, "snow/ice" ) )} -> short veg | ... K7: {=_xlfn.LET(_xlpm.x, VLOOKUP($A7, scenarios!$A$2:$K$109, K$1, 0), _xlfn.IFS( _xlpm.x=250, "built up", _xlpm.x=244, "cropland", OR(AND(_xlpm.x>=27,_xlpm.x<=48), AND(_xlpm.x>=127,_xlpm.x<=148)), "tall veg", OR(AND(_xlpm.x>=5,_xlpm.x<=26), AND(_xlpm.x>=105,_xlpm.x<=126)), "short veg", AND(_xlpm.x>=200,_xlpm.x<=204), "wetland", OR(AND(_xlpm.x>=0,_xlpm.x<=4), AND(_xlpm.x>=100,_xlpm.x<=104)), "bare", AND(_xlpm.x>=205,_xlpm.x<=207), "water", _xlpm.x=241, "snow/ice" ) )} -> short veg | L7: {=IFERROR(_xlfn.SWITCH(VLOOKUP($A7, scenarios!$A$2:$P$109, L$1, 0), 1, "Permanent agriculture", 2, "Hard commodities", 3, "Shifting cultivation", 4, "Logging", 5, "Wildfire", 6, "Settlements & infrastructure", 7, "Other natural disturbances"), "")} -> Permanent agriculture | M7: =_xlfn.LET(_xlpm.x, scenarios!M6, IF(OR(ISERROR(_xlpm.x), _xlpm.x=0), "", _xlpm.x)) -> 2015 | N7: =_xlfn.LET(_xlpm.x, scenarios!N6, IF(OR(ISERROR(_xlpm.x), _xlpm.x=0), "", _xlpm.x)) | O7: =_xlfn.LET(_xlpm.x, scenarios!O6, IF(OR(ISERROR(_xlpm.x), _xlpm.x=0), "", _xlpm.x)) | P7: =_xlfn.LET(_xlpm.x, scenarios!P6, IF(OR(ISERROR(_xlpm.x), _xlpm.x=0), "", _xlpm.x)) | Q7: =_xlfn.LET(_xlpm.x, scenarios!Q6, IF(OR(ISERROR(_xlpm.x), _xlpm.x=0), "", _xlpm.x)) | R7: =_xlfn.LET(_xlpm.x, scenarios!R6, IF(OR(ISERROR(_xlpm.x), _xlpm.x=0), "", _xlpm.x)) -> TRUE
A8: 6 | B8: {=_xlfn.LET(_xlpm.x, VLOOKUP($A8, scenarios!$A$2:$K$109, B$1, 0), _xlfn.IFS( _xlpm.x=250, "built up", _xlpm.x=244, "cropland", OR(AND(_xlpm.x>=27,_xlpm.x<=48), AND(_xlpm.x>=127,_xlpm.x<=148)), "tall veg", OR(AND(_xlpm.x>=5,_xlpm.x<=26), AND(_xlpm.x>=105,_xlpm.x<=126)), "short veg", AND(_xlpm.x>=200,_xlpm.x<=204), "wetland", OR(AND(_xlpm.x>=0,_xlpm.x<=4), AND(_xlpm.x>=100,_xlpm.x<=104)), "bare", AND(_xlpm.x>=205,_xlpm.x<=207), "water", _xlpm.x=241, "snow/ice" ) )} -> short veg | C8: {=_xlfn.LET(_xlpm.x, VLOOKUP($A8, scenarios!$A$2:$K$109, C$1, 0), _xlfn.IFS( _xlpm.x=250, "built up", _xlpm.x=244, "cropland", OR(AND(_xlpm.x>=27,_xlpm.x<=48), AND(_xlpm.x>=127,_xlpm.x<=148)), "tall veg", OR(AND(_xlpm.x>=5,_xlpm.x<=26), AND(_xlpm.x>=105,_xlpm.x<=126)), "short veg", AND(_xlpm.x>=200,_xlpm.x<=204), "wetland", OR(AND(_xlpm.x>=0,_xlpm.x<=4), AND(_xlpm.x>=100,_xlpm.x<=104)), "bare", AND(_xlpm.x>=205,_xlpm.x<=207), "water", _xlpm.x=241, "snow/ice" ) )} -> short veg | D8: {=_xlfn.LET(_xlpm.x, VLOOKUP($A8, scenarios!$A$2:$K$109, D$1, 0), _xlfn.IFS( _xlpm.x=250, "built up", _xlpm.x=244, "cropland", OR(AND(_xlpm.x>=27,_xlpm.x<=48), AND(_xlpm.x>=127,_xlpm.x<=148)), "tall veg", OR(AND(_xlpm.x>=5,_xlpm.x<=26), AND(_xlpm.x>=105,_xlpm.x<=126)), "short veg", AND(_xlpm.x>=200,_xlpm.x<=204), "wetland", OR(AND(_xlpm.x>=0,_xlpm.x<=4), AND(_xlpm.x>=100,_xlpm.x<=104)), "bare", AND(_xlpm.x>=205,_xlpm.x<=207), "water", _xlpm.x=241, "snow/ice" ) )} -> short veg | E8: {=_xlfn.LET(_xlpm.x, VLOOKUP($A8, scenarios!$A$2:$K$109, E$1, 0), _xlfn.IFS( _xlpm.x=250, "built up", _xlpm.x=244, "cropland", OR(AND(_xlpm.x>=27,_xlpm.x<=48), AND(_xlpm.x>=127,_xlpm.x<=148)), "tall veg", OR(AND(_xlpm.x>=5,_xlpm.x<=26), AND(_xlpm.x>=105,_xlpm.x<=126)), "short veg", AND(_xlpm.x>=200,_xlpm.x<=204), "wetland", OR(AND(_xlpm.x>=0,_xlpm.x<=4), AND(_xlpm.x>=100,_xlpm.x<=104)), "bare", AND(_xlpm.x>=205,_xlpm.x<=207), "water", _xlpm.x=241, "snow/ice" ) )} -> short veg | F8: {=_xlfn.LET(_xlpm.x, VLOOKUP($A8, scenarios!$A$2:$K$109, F$1, 0), _xlfn.IFS( _xlpm.x=250, "built up", _xlpm.x=244, "cropland", OR(AND(_xlpm.x>=27,_xlpm.x<=48), AND(_xlpm.x>=127,_xlpm.x<=148)), "tall veg", OR(AND(_xlpm.x>=5,_xlpm.x<=26), AND(_xlpm.x>=105,_xlpm.x<=126)), "short veg", AND(_xlpm.x>=200,_xlpm.x<=204), "wetland", OR(AND(_xlpm.x>=0,_xlpm.x<=4), AND(_xlpm.x>=100,_xlpm.x<=104)), "bare", AND(_xlpm.x>=205,_xlpm.x<=207), "water", _xlpm.x=241, "snow/ice" ) )} -> short veg | G8: {=_xlfn.LET(_xlpm.x, VLOOKUP($A8, scenarios!$A$2:$K$109, G$1, 0), _xlfn.IFS( _xlpm.x=250, "built up", _xlpm.x=244, "cropland", OR(AND(_xlpm.x>=27,_xlpm.x<=48), AND(_xlpm.x>=127,_xlpm.x<=148)), "tall veg", OR(AND(_xlpm.x>=5,_xlpm.x<=26), AND(_xlpm.x>=105,_xlpm.x<=126)), "short veg", AND(_xlpm.x>=200,_xlpm.x<=204), "wetland", OR(AND(_xlpm.x>=0,_xlpm.x<=4), AND(_xlpm.x>=100,_xlpm.x<=104)), "bare", AND(_xlpm.x>=205,_xlpm.x<=207), "water", _xlpm.x=241, "snow/ice" ) )} -> short veg | H8: {=_xlfn.LET(_xlpm.x, VLOOKUP($A8, scenarios!$A$2:$K$109, H$1, 0), _xlfn.IFS( _xlpm.x=250, "built up", _xlpm.x=244, "cropland", OR(AND(_xlpm.x>=27,_xlpm.x<=48), AND(_xlpm.x>=127,_xlpm.x<=148)), "tall veg", OR(AND(_xlpm.x>=5,_xlpm.x<=26), AND(_xlpm.x>=105,_xlpm.x<=126)), "short veg", AND(_xlpm.x>=200,_xlpm.x<=204), "wetland", OR(AND(_xlpm.x>=0,_xlpm.x<=4), AND(_xlpm.x>=100,_xlpm.x<=104)), "bare", AND(_xlpm.x>=205,_xlpm.x<=207), "water", _xlpm.x=241, "snow/ice" ) )} -> short veg | I8: {=_xlfn.LET(_xlpm.x, VLOOKUP($A8, scenarios!$A$2:$K$109, I$1, 0), _xlfn.IFS( _xlpm.x=250, "built up", _xlpm.x=244, "cropland", OR(AND(_xlpm.x>=27,_xlpm.x<=48), AND(_xlpm.x>=127,_xlpm.x<=148)), "tall veg", OR(AND(_xlpm.x>=5,_xlpm.x<=26), AND(_xlpm.x>=105,_xlpm.x<=126)), "short veg", AND(_xlpm.x>=200,_xlpm.x<=204), "wetland", OR(AND(_xlpm.x>=0,_xlpm.x<=4), AND(_xlpm.x>=100,_xlpm.x<=104)), "bare", AND(_xlpm.x>=205,_xlpm.x<=207), "water", _xlpm.x=241, "snow/ice" ) )} -> short veg | ... K8: {=_xlfn.LET(_xlpm.x, VLOOKUP($A8, scenarios!$A$2:$K$109, K$1, 0), _xlfn.IFS( _xlpm.x=250, "built up", _xlpm.x=244, "cropland", OR(AND(_xlpm.x>=27,_xlpm.x<=48), AND(_xlpm.x>=127,_xlpm.x<=148)), "tall veg", OR(AND(_xlpm.x>=5,_xlpm.x<=26), AND(_xlpm.x>=105,_xlpm.x<=126)), "short veg", AND(_xlpm.x>=200,_xlpm.x<=204), "wetland", OR(AND(_xlpm.x>=0,_xlpm.x<=4), AND(_xlpm.x>=100,_xlpm.x<=104)), "bare", AND(_xlpm.x>=205,_xlpm.x<=207), "water", _xlpm.x=241, "snow/ice" ) )} -> short veg | L8: {=IFERROR(_xlfn.SWITCH(VLOOKUP($A8, scenarios!$A$2:$P$109, L$1, 0), 1, "Permanent agriculture", 2, "Hard commodities", 3, "Shifting cultivation", 4, "Logging", 5, "Wildfire", 6, "Settlements & infrastructure", 7, "Other natural disturbances"), "")} -> Permanent agriculture | M8: =_xlfn.LET(_xlpm.x, scenarios!M7, IF(OR(ISERROR(_xlpm.x), _xlpm.x=0), "", _xlpm.x)) -> 2020 | N8: =_xlfn.LET(_xlpm.x, scenarios!N7, IF(OR(ISERROR(_xlpm.x), _xlpm.x=0), "", _xlpm.x)) | O8: =_xlfn.LET(_xlpm.x, scenarios!O7, IF(OR(ISERROR(_xlpm.x), _xlpm.x=0), "", _xlpm.x)) | P8: =_xlfn.LET(_xlpm.x, scenarios!P7, IF(OR(ISERROR(_xlpm.x), _xlpm.x=0), "", _xlpm.x)) | Q8: =_xlfn.LET(_xlpm.x, scenarios!Q7, IF(OR(ISERROR(_xlpm.x), _xlpm.x=0), "", _xlpm.x)) | R8: =_xlfn.LET(_xlpm.x, scenarios!R7, IF(OR(ISERROR(_xlpm.x), _xlpm.x=0), "", _xlpm.x))
A9: 7 | B9: {=_xlfn.LET(_xlpm.x, VLOOKUP($A9, scenarios!$A$2:$K$109, B$1, 0), _xlfn.IFS( _xlpm.x=250, "built up", _xlpm.x=244, "cropland", OR(AND(_xlpm.x>=27,_xlpm.x<=48), AND(_xlpm.x>=127,_xlpm.x<=148)), "tall veg", OR(AND(_xlpm.x>=5,_xlpm.x<=26), AND(_xlpm.x>=105,_xlpm.x<=126)), "short veg", AND(_xlpm.x>=200,_xlpm.x<=204), "wetland", OR(AND(_xlpm.x>=0,_xlpm.x<=4), AND(_xlpm.x>=100,_xlpm.x<=104)), "bare", AND(_xlpm.x>=205,_xlpm.x<=207), "water", _xlpm.x=241, "snow/ice" ) )} -> short veg | C9: {=_xlfn.LET(_xlpm.x, VLOOKUP($A9, scenarios!$A$2:$K$109, C$1, 0), _xlfn.IFS( _xlpm.x=250, "built up", _xlpm.x=244, "cropland", OR(AND(_xlpm.x>=27,_xlpm.x<=48), AND(_xlpm.x>=127,_xlpm.x<=148)), "tall veg", OR(AND(_xlpm.x>=5,_xlpm.x<=26), AND(_xlpm.x>=105,_xlpm.x<=126)), "short veg", AND(_xlpm.x>=200,_xlpm.x<=204), "wetland", OR(AND(_xlpm.x>=0,_xlpm.x<=4), AND(_xlpm.x>=100,_xlpm.x<=104)), "bare", AND(_xlpm.x>=205,_xlpm.x<=207), "water", _xlpm.x=241, "snow/ice" ) )} -> short veg | D9: {=_xlfn.LET(_xlpm.x, VLOOKUP($A9, scenarios!$A$2:$K$109, D$1, 0), _xlfn.IFS( _xlpm.x=250, "built up", _xlpm.x=244, "cropland", OR(AND(_xlpm.x>=27,_xlpm.x<=48), AND(_xlpm.x>=127,_xlpm.x<=148)), "tall veg", OR(AND(_xlpm.x>=5,_xlpm.x<=26), AND(_xlpm.x>=105,_xlpm.x<=126)), "short veg", AND(_xlpm.x>=200,_xlpm.x<=204), "wetland", OR(AND(_xlpm.x>=0,_xlpm.x<=4), AND(_xlpm.x>=100,_xlpm.x<=104)), "bare", AND(_xlpm.x>=205,_xlpm.x<=207), "water", _xlpm.x=241, "snow/ice" ) )} -> short veg | E9: {=_xlfn.LET(_xlpm.x, VLOOKUP($A9, scenarios!$A$2:$K$109, E$1, 0), _xlfn.IFS( _xlpm.x=250, "built up", _xlpm.x=244, "cropland", OR(AND(_xlpm.x>=27,_xlpm.x<=48), AND(_xlpm.x>=127,_xlpm.x<=148)), "tall veg", OR(AND(_xlpm.x>=5,_xlpm.x<=26), AND(_xlpm.x>=105,_xlpm.x<=126)), "short veg", AND(_xlpm.x>=200,_xlpm.x<=204), "wetland", OR(AND(_xlpm.x>=0,_xlpm.x<=4), AND(_xlpm.x>=100,_xlpm.x<=104)), "bare", AND(_xlpm.x>=205,_xlpm.x<=207), "water", _xlpm.x=241, "snow/ice" ) )} -> short veg | F9: {=_xlfn.LET(_xlpm.x, VLOOKUP($A9, scenarios!$A$2:$K$109, F$1, 0), _xlfn.IFS( _xlpm.x=250, "built up", _xlpm.x=244, "cropland", OR(AND(_xlpm.x>=27,_xlpm.x<=48), AND(_xlpm.x>=127,_xlpm.x<=148)), "tall veg", OR(AND(_xlpm.x>=5,_xlpm.x<=26), AND(_xlpm.x>=105,_xlpm.x<=126)), "short veg", AND(_xlpm.x>=200,_xlpm.x<=204), "wetland", OR(AND(_xlpm.x>=0,_xlpm.x<=4), AND(_xlpm.x>=100,_xlpm.x<=104)), "bare", AND(_xlpm.x>=205,_xlpm.x<=207), "water", _xlpm.x=241, "snow/ice" ) )} -> short veg | G9: {=_xlfn.LET(_xlpm.x, VLOOKUP($A9, scenarios!$A$2:$K$109, G$1, 0), _xlfn.IFS( _xlpm.x=250, "built up", _xlpm.x=244, "cropland", OR(AND(_xlpm.x>=27,_xlpm.x<=48), AND(_xlpm.x>=127,_xlpm.x<=148)), "tall veg", OR(AND(_xlpm.x>=5,_xlpm.x<=26), AND(_xlpm.x>=105,_xlpm.x<=126)), "short veg", AND(_xlpm.x>=200,_xlpm.x<=204), "wetland", OR(AND(_xlpm.x>=0,_xlpm.x<=4), AND(_xlpm.x>=100,_xlpm.x<=104)), "bare", AND(_xlpm.x>=205,_xlpm.x<=207), "water", _xlpm.x=241, "snow/ice" ) )} -> short veg | H9: {=_xlfn.LET(_xlpm.x, VLOOKUP($A9, scenarios!$A$2:$K$109, H$1, 0), _xlfn.IFS( _xlpm.x=250, "built up", _xlpm.x=244, "cropland", OR(AND(_xlpm.x>=27,_xlpm.x<=48), AND(_xlpm.x>=127,_xlpm.x<=148)), "tall veg", OR(AND(_xlpm.x>=5,_xlpm.x<=26), AND(_xlpm.x>=105,_xlpm.x<=126)), "short veg", AND(_xlpm.x>=200,_xlpm.x<=204), "wetland", OR(AND(_xlpm.x>=0,_xlpm.x<=4), AND(_xlpm.x>=100,_xlpm.x<=104)), "bare", AND(_xlpm.x>=205,_xlpm.x<=207), "water", _xlpm.x=241, "snow/ice" ) )} -> short veg | I9: {=_xlfn.LET(_xlpm.x, VLOOKUP($A9, scenarios!$A$2:$K$109, I$1, 0), _xlfn.IFS( _xlpm.x=250, "built up", _xlpm.x=244, "cropland", OR(AND(_xlpm.x>=27,_xlpm.x<=48), AND(_xlpm.x>=127,_xlpm.x<=148)), "tall veg", OR(AND(_xlpm.x>=5,_xlpm.x<=26), AND(_xlpm.x>=105,_xlpm.x<=126)), "short veg", AND(_xlpm.x>=200,_xlpm.x<=204), "wetland", OR(AND(_xlpm.x>=0,_xlpm.x<=4), AND(_xlpm.x>=100,_xlpm.x<=104)), "bare", AND(_xlpm.x>=205,_xlpm.x<=207), "water", _xlpm.x=241, "snow/ice" ) )} -> short veg | ... K9: {=_xlfn.LET(_xlpm.x, VLOOKUP($A9, scenarios!$A$2:$K$109, K$1, 0), _xlfn.IFS( _xlpm.x=250, "built up", _xlpm.x=244, "cropland", OR(AND(_xlpm.x>=27,_xlpm.x<=48), AND(_xlpm.x>=127,_xlpm.x<=148)), "tall veg", OR(AND(_xlpm.x>=5,_xlpm.x<=26), AND(_xlpm.x>=105,_xlpm.x<=126)), "short veg", AND(_xlpm.x>=200,_xlpm.x<=204), "wetland", OR(AND(_xlpm.x>=0,_xlpm.x<=4), AND(_xlpm.x>=100,_xlpm.x<=104)), "bare", AND(_xlpm.x>=205,_xlpm.x<=207), "water", _xlpm.x=241, "snow/ice" ) )} -> short veg | L9: {=IFERROR(_xlfn.SWITCH(VLOOKUP($A9, scenarios!$A$2:$P$109, L$1, 0), 1, "Permanent agriculture", 2, "Hard commodities", 3, "Shifting cultivation", 4, "Logging", 5, "Wildfire", 6, "Settlements & infrastructure", 7, "Other natural disturbances"), "")} -> Permanent agriculture | M9: =_xlfn.LET(_xlpm.x, scenarios!M8, IF(OR(ISERROR(_xlpm.x), _xlpm.x=0), "", _xlpm.x)) -> 2020 | N9: =_xlfn.LET(_xlpm.x, scenarios!N8, IF(OR(ISERROR(_xlpm.x), _xlpm.x=0), "", _xlpm.x)) | O9: =_xlfn.LET(_xlpm.x, scenarios!O8, IF(OR(ISERROR(_xlpm.x), _xlpm.x=0), "", _xlpm.x)) | P9: =_xlfn.LET(_xlpm.x, scenarios!P8, IF(OR(ISERROR(_xlpm.x), _xlpm.x=0), "", _xlpm.x)) | Q9: =_xlfn.LET(_xlpm.x, scenarios!Q8, IF(OR(ISERROR(_xlpm.x), _xlpm.x=0), "", _xlpm.x)) | R9: =_xlfn.LET(_xlpm.x, scenarios!R8, IF(OR(ISERROR(_xlpm.x), _xlpm.x=0), "", _xlpm.x)) -> TRUE
A10: 8 | B10: {=_xlfn.LET(_xlpm.x, VLOOKUP($A10, scenarios!$A$2:$K$109, B$1, 0), _xlfn.IFS( _xlpm.x=250, "built up", _xlpm.x=244, "cropland", OR(AND(_xlpm.x>=27,_xlpm.x<=48), AND(_xlpm.x>=127,_xlpm.x<=148)), "tall veg", OR(AND(_xlpm.x>=5,_xlpm.x<=26), AND(_xlpm.x>=105,_xlpm.x<=126)), "short veg", AND(_xlpm.x>=200,_xlpm.x<=204), "wetland", OR(AND(_xlpm.x>=0,_xlpm.x<=4), AND(_xlpm.x>=100,_xlpm.x<=104)), "bare", AND(_xlpm.x>=205,_xlpm.x<=207), "water", _xlpm.x=241, "snow/ice" ) )} -> short veg | C10: {=_xlfn.LET(_xlpm.x, VLOOKUP($A10, scenarios!$A$2:$K$109, C$1, 0), _xlfn.IFS( _xlpm.x=250, "built up", _xlpm.x=244, "cropland", OR(AND(_xlpm.x>=27,_xlpm.x<=48), AND(_xlpm.x>=127,_xlpm.x<=148)), "tall veg", OR(AND(_xlpm.x>=5,_xlpm.x<=26), AND(_xlpm.x>=105,_xlpm.x<=126)), "short veg", AND(_xlpm.x>=200,_xlpm.x<=204), "wetland", OR(AND(_xlpm.x>=0,_xlpm.x<=4), AND(_xlpm.x>=100,_xlpm.x<=104)), "bare", AND(_xlpm.x>=205,_xlpm.x<=207), "water", _xlpm.x=241, "snow/ice" ) )} -> short veg | D10: {=_xlfn.LET(_xlpm.x, VLOOKUP($A10, scenarios!$A$2:$K$109, D$1, 0), _xlfn.IFS( _xlpm.x=250, "built up", _xlpm.x=244, "cropland", OR(AND(_xlpm.x>=27,_xlpm.x<=48), AND(_xlpm.x>=127,_xlpm.x<=148)), "tall veg", OR(AND(_xlpm.x>=5,_xlpm.x<=26), AND(_xlpm.x>=105,_xlpm.x<=126)), "short veg", AND(_xlpm.x>=200,_xlpm.x<=204), "wetland", OR(AND(_xlpm.x>=0,_xlpm.x<=4), AND(_xlpm.x>=100,_xlpm.x<=104)), "bare", AND(_xlpm.x>=205,_xlpm.x<=207), "water", _xlpm.x=241, "snow/ice" ) )} -> short veg | E10: {=_xlfn.LET(_xlpm.x, VLOOKUP($A10, scenarios!$A$2:$K$109, E$1, 0), _xlfn.IFS( _xlpm.x=250, "built up", _xlpm.x=244, "cropland", OR(AND(_xlpm.x>=27,_xlpm.x<=48), AND(_xlpm.x>=127,_xlpm.x<=148)), "tall veg", OR(AND(_xlpm.x>=5,_xlpm.x<=26), AND(_xlpm.x>=105,_xlpm.x<=126)), "short veg", AND(_xlpm.x>=200,_xlpm.x<=204), "wetland", OR(AND(_xlpm.x>=0,_xlpm.x<=4), AND(_xlpm.x>=100,_xlpm.x<=104)), "bare", AND(_xlpm.x>=205,_xlpm.x<=207), "water", _xlpm.x=241, "snow/ice" ) )} -> short veg | F10: {=_xlfn.LET(_xlpm.x, VLOOKUP($A10, scenarios!$A$2:$K$109, F$1, 0), _xlfn.IFS( _xlpm.x=250, "built up", _xlpm.x=244, "cropland", OR(AND(_xlpm.x>=27,_xlpm.x<=48), AND(_xlpm.x>=127,_xlpm.x<=148)), "tall veg", OR(AND(_xlpm.x>=5,_xlpm.x<=26), AND(_xlpm.x>=105,_xlpm.x<=126)), "short veg", AND(_xlpm.x>=200,_xlpm.x<=204), "wetland", OR(AND(_xlpm.x>=0,_xlpm.x<=4), AND(_xlpm.x>=100,_xlpm.x<=104)), "bare", AND(_xlpm.x>=205,_xlpm.x<=207), "water", _xlpm.x=241, "snow/ice" ) )} -> short veg | G10: {=_xlfn.LET(_xlpm.x, VLOOKUP($A10, scenarios!$A$2:$K$109, G$1, 0), _xlfn.IFS( _xlpm.x=250, "built up", _xlpm.x=244, "cropland", OR(AND(_xlpm.x>=27,_xlpm.x<=48), AND(_xlpm.x>=127,_xlpm.x<=148)), "tall veg", OR(AND(_xlpm.x>=5,_xlpm.x<=26), AND(_xlpm.x>=105,_xlpm.x<=126)), "short veg", AND(_xlpm.x>=200,_xlpm.x<=204), "wetland", OR(AND(_xlpm.x>=0,_xlpm.x<=4), AND(_xlpm.x>=100,_xlpm.x<=104)), "bare", AND(_xlpm.x>=205,_xlpm.x<=207), "water", _xlpm.x=241, "snow/ice" ) )} -> short veg | H10: {=_xlfn.LET(_xlpm.x, VLOOKUP($A10, scenarios!$A$2:$K$109, H$1, 0), _xlfn.IFS( _xlpm.x=250, "built up", _xlpm.x=244, "cropland", OR(AND(_xlpm.x>=27,_xlpm.x<=48), AND(_xlpm.x>=127,_xlpm.x<=148)), "tall veg", OR(AND(_xlpm.x>=5,_xlpm.x<=26), AND(_xlpm.x>=105,_xlpm.x<=126)), "short veg", AND(_xlpm.x>=200,_xlpm.x<=204), "wetland", OR(AND(_xlpm.x>=0,_xlpm.x<=4), AND(_xlpm.x>=100,_xlpm.x<=104)), "bare", AND(_xlpm.x>=205,_xlpm.x<=207), "water", _xlpm.x=241, "snow/ice" ) )} -> short veg | I10: {=_xlfn.LET(_xlpm.x, VLOOKUP($A10, scenarios!$A$2:$K$109, I$1, 0), _xlfn.IFS( _xlpm.x=250, "built up", _xlpm.x=244, "cropland", OR(AND(_xlpm.x>=27,_xlpm.x<=48), AND(_xlpm.x>=127,_xlpm.x<=148)), "tall veg", OR(AND(_xlpm.x>=5,_xlpm.x<=26), AND(_xlpm.x>=105,_xlpm.x<=126)), "short veg", AND(_xlpm.x>=200,_xlpm.x<=204), "wetland", OR(AND(_xlpm.x>=0,_xlpm.x<=4), AND(_xlpm.x>=100,_xlpm.x<=104)), "bare", AND(_xlpm.x>=205,_xlpm.x<=207), "water", _xlpm.x=241, "snow/ice" ) )} -> short veg | ... K10: {=_xlfn.LET(_xlpm.x, VLOOKUP($A10, scenarios!$A$2:$K$109, K$1, 0), _xlfn.IFS( _xlpm.x=250, "built up", _xlpm.x=244, "cropland", OR(AND(_xlpm.x>=27,_xlpm.x<=48), AND(_xlpm.x>=127,_xlpm.x<=148)), "tall veg", OR(AND(_xlpm.x>=5,_xlpm.x<=26), AND(_xlpm.x>=105,_xlpm.x<=126)), "short veg", AND(_xlpm.x>=200,_xlpm.x<=204), "wetland", OR(AND(_xlpm.x>=0,_xlpm.x<=4), AND(_xlpm.x>=100,_xlpm.x<=104)), "bare", AND(_xlpm.x>=205,_xlpm.x<=207), "water", _xlpm.x=241, "snow/ice" ) )} -> short veg | L10: {=IFERROR(_xlfn.SWITCH(VLOOKUP($A10, scenarios!$A$2:$P$109, L$1, 0), 1, "Permanent agriculture", 2, "Hard commodities", 3, "Shifting cultivation", 4, "Logging", 5, "Wildfire", 6, "Settlements & infrastructure", 7, "Other natural disturbances"), "")} -> Shifting cultivation | M10: =_xlfn.LET(_xlpm.x, scenarios!M9, IF(OR(ISERROR(_xlpm.x), _xlpm.x=0), "", _xlpm.x)) -> 2015 | N10: =_xlfn.LET(_xlpm.x, scenarios!N9, IF(OR(ISERROR(_xlpm.x), _xlpm.x=0), "", _xlpm.x)) | O10: =_xlfn.LET(_xlpm.x, scenarios!O9, IF(OR(ISERROR(_xlpm.x), _xlpm.x=0), "", _xlpm.x)) | P10: =_xlfn.LET(_xlpm.x, scenarios!P9, IF(OR(ISERROR(_xlpm.x), _xlpm.x=0), "", _xlpm.x)) | Q10: =_xlfn.LET(_xlpm.x, scenarios!Q9, IF(OR(ISERROR(_xlpm.x), _xlpm.x=0), "", _xlpm.x)) | R10: =_xlfn.LET(_xlpm.x, scenarios!R9, IF(OR(ISERROR(_xlpm.x), _xlpm.x=0), "", _xlpm.x))
A11: 9 | B11: {=_xlfn.LET(_xlpm.x, VLOOKUP($A11, scenarios!$A$2:$K$109, B$1, 0), _xlfn.IFS( _xlpm.x=250, "built up", _xlpm.x=244, "cropland", OR(AND(_xlpm.x>=27,_xlpm.x<=48), AND(_xlpm.x>=127,_xlpm.x<=148)), "tall veg", OR(AND(_xlpm.x>=5,_xlpm.x<=26), AND(_xlpm.x>=105,_xlpm.x<=126)), "short veg", AND(_xlpm.x>=200,_xlpm.x<=204), "wetland", OR(AND(_xlpm.x>=0,_xlpm.x<=4), AND(_xlpm.x>=100,_xlpm.x<=104)), "bare", AND(_xlpm.x>=205,_xlpm.x<=207), "water", _xlpm.x=241, "snow/ice" ) )} -> short veg | C11: {=_xlfn.LET(_xlpm.x, VLOOKUP($A11, scenarios!$A$2:$K$109, C$1, 0), _xlfn.IFS( _xlpm.x=250, "built up", _xlpm.x=244, "cropland", OR(AND(_xlpm.x>=27,_xlpm.x<=48), AND(_xlpm.x>=127,_xlpm.x<=148)), "tall veg", OR(AND(_xlpm.x>=5,_xlpm.x<=26), AND(_xlpm.x>=105,_xlpm.x<=126)), "short veg", AND(_xlpm.x>=200,_xlpm.x<=204), "wetland", OR(AND(_xlpm.x>=0,_xlpm.x<=4), AND(_xlpm.x>=100,_xlpm.x<=104)), "bare", AND(_xlpm.x>=205,_xlpm.x<=207), "water", _xlpm.x=241, "snow/ice" ) )} -> short veg | D11: {=_xlfn.LET(_xlpm.x, VLOOKUP($A11, scenarios!$A$2:$K$109, D$1, 0), _xlfn.IFS( _xlpm.x=250, "built up", _xlpm.x=244, "cropland", OR(AND(_xlpm.x>=27,_xlpm.x<=48), AND(_xlpm.x>=127,_xlpm.x<=148)), "tall veg", OR(AND(_xlpm.x>=5,_xlpm.x<=26), AND(_xlpm.x>=105,_xlpm.x<=126)), "short veg", AND(_xlpm.x>=200,_xlpm.x<=204), "wetland", OR(AND(_xlpm.x>=0,_xlpm.x<=4), AND(_xlpm.x>=100,_xlpm.x<=104)), "bare", AND(_xlpm.x>=205,_xlpm.x<=207), "water", _xlpm.x=241, "snow/ice" ) )} -> short veg | E11: {=_xlfn.LET(_xlpm.x, VLOOKUP($A11, scenarios!$A$2:$K$109, E$1, 0), _xlfn.IFS( _xlpm.x=250, "built up", _xlpm.x=244, "cropland", OR(AND(_xlpm.x>=27,_xlpm.x<=48), AND(_xlpm.x>=127,_xlpm.x<=148)), "tall veg", OR(AND(_xlpm.x>=5,_xlpm.x<=26), AND(_xlpm.x>=105,_xlpm.x<=126)), "short veg", AND(_xlpm.x>=200,_xlpm.x<=204), "wetland", OR(AND(_xlpm.x>=0,_xlpm.x<=4), AND(_xlpm.x>=100,_xlpm.x<=104)), "bare", AND(_xlpm.x>=205,_xlpm.x<=207), "water", _xlpm.x=241, "snow/ice" ) )} -> short veg | F11: {=_xlfn.LET(_xlpm.x, VLOOKUP($A11, scenarios!$A$2:$K$109, F$1, 0), _xlfn.IFS( _xlpm.x=250, "built up", _xlpm.x=244, "cropland", OR(AND(_xlpm.x>=27,_xlpm.x<=48), AND(_xlpm.x>=127,_xlpm.x<=148)), "tall veg", OR(AND(_xlpm.x>=5,_xlpm.x<=26), AND(_xlpm.x>=105,_xlpm.x<=126)), "short veg", AND(_xlpm.x>=200,_xlpm.x<=204), "wetland", OR(AND(_xlpm.x>=0,_xlpm.x<=4), AND(_xlpm.x>=100,_xlpm.x<=104)), "bare", AND(_xlpm.x>=205,_xlpm.x<=207), "water", _xlpm.x=241, "snow/ice" ) )} -> short veg | G11: {=_xlfn.LET(_xlpm.x, VLOOKUP($A11, scenarios!$A$2:$K$109, G$1, 0), _xlfn.IFS( _xlpm.x=250, "built up", _xlpm.x=244, "cropland", OR(AND(_xlpm.x>=27,_xlpm.x<=48), AND(_xlpm.x>=127,_xlpm.x<=148)), "tall veg", OR(AND(_xlpm.x>=5,_xlpm.x<=26), AND(_xlpm.x>=105,_xlpm.x<=126)), "short veg", AND(_xlpm.x>=200,_xlpm.x<=204), "wetland", OR(AND(_xlpm.x>=0,_xlpm.x<=4), AND(_xlpm.x>=100,_xlpm.x<=104)), "bare", AND(_xlpm.x>=205,_xlpm.x<=207), "water", _xlpm.x=241, "snow/ice" ) )} -> short veg | H11: {=_xlfn.LET(_xlpm.x, VLOOKUP($A11, scenarios!$A$2:$K$109, H$1, 0), _xlfn.IFS( _xlpm.x=250, "built up", _xlpm.x=244, "cropland", OR(AND(_xlpm.x>=27,_xlpm.x<=48), AND(_xlpm.x>=127,_xlpm.x<=148)), "tall veg", OR(AND(_xlpm.x>=5,_xlpm.x<=26), AND(_xlpm.x>=105,_xlpm.x<=126)), "short veg", AND(_xlpm.x>=200,_xlpm.x<=204), "wetland", OR(AND(_xlpm.x>=0,_xlpm.x<=4), AND(_xlpm.x>=100,_xlpm.x<=104)), "bare", AND(_xlpm.x>=205,_xlpm.x<=207), "water", _xlpm.x=241, "snow/ice" ) )} -> short veg | I11: {=_xlfn.LET(_xlpm.x, VLOOKUP($A11, scenarios!$A$2:$K$109, I$1, 0), _xlfn.IFS( _xlpm.x=250, "built up", _xlpm.x=244, "cropland", OR(AND(_xlpm.x>=27,_xlpm.x<=48), AND(_xlpm.x>=127,_xlpm.x<=148)), "tall veg", OR(AND(_xlpm.x>=5,_xlpm.x<=26), AND(_xlpm.x>=105,_xlpm.x<=126)), "short veg", AND(_xlpm.x>=200,_xlpm.x<=204), "wetland", OR(AND(_xlpm.x>=0,_xlpm.x<=4), AND(_xlpm.x>=100,_xlpm.x<=104)), "bare", AND(_xlpm.x>=205,_xlpm.x<=207), "water", _xlpm.x=241, "snow/ice" ) )} -> short veg | ... K11: {=_xlfn.LET(_xlpm.x, VLOOKUP($A11, scenarios!$A$2:$K$109, K$1, 0), _xlfn.IFS( _xlpm.x=250, "built up", _xlpm.x=244, "cropland", OR(AND(_xlpm.x>=27,_xlpm.x<=48), AND(_xlpm.x>=127,_xlpm.x<=148)), "tall veg", OR(AND(_xlpm.x>=5,_xlpm.x<=26), AND(_xlpm.x>=105,_xlpm.x<=126)), "short veg", AND(_xlpm.x>=200,_xlpm.x<=204), "wetland", OR(AND(_xlpm.x>=0,_xlpm.x<=4), AND(_xlpm.x>=100,_xlpm.x<=104)), "bare", AND(_xlpm.x>=205,_xlpm.x<=207), "water", _xlpm.x=241, "snow/ice" ) )} -> short veg | L11: {=IFERROR(_xlfn.SWITCH(VLOOKUP($A11, scenarios!$A$2:$P$109, L$1, 0), 1, "Permanent agriculture", 2, "Hard commodities", 3, "Shifting cultivation", 4, "Logging", 5, "Wildfire", 6, "Settlements & infrastructure", 7, "Other natural disturbances"), "")} -> Logging | M11: =_xlfn.LET(_xlpm.x, scenarios!M10, IF(OR(ISERROR(_xlpm.x), _xlpm.x=0), "", _xlpm.x)) -> 2015 | N11: =_xlfn.LET(_xlpm.x, scenarios!N10, IF(OR(ISERROR(_xlpm.x), _xlpm.x=0), "", _xlpm.x)) | O11: =_xlfn.LET(_xlpm.x, scenarios!O10, IF(OR(ISERROR(_xlpm.x), _xlpm.x=0), "", _xlpm.x)) | P11: =_xlfn.LET(_xlpm.x, scenarios!P10, IF(OR(ISERROR(_xlpm.x), _xlpm.x=0), "", _xlpm.x)) | Q11: =_xlfn.LET(_xlpm.x, scenarios!Q10, IF(OR(ISERROR(_xlpm.x), _xlpm.x=0), "", _xlpm.x)) | R11: =_xlfn.LET(_xlpm.x, scenarios!R10, IF(OR(ISERROR(_xlpm.x), _xlpm.x=0), "", _xlpm.x))
A12: 10 | B12: {=_xlfn.LET(_xlpm.x, VLOOKUP($A12, scenarios!$A$2:$K$109, B$1, 0), _xlfn.IFS( _xlpm.x=250, "built up", _xlpm.x=244, "cropland", OR(AND(_xlpm.x>=27,_xlpm.x<=48), AND(_xlpm.x>=127,_xlpm.x<=148)), "tall veg", OR(AND(_xlpm.x>=5,_xlpm.x<=26), AND(_xlpm.x>=105,_xlpm.x<=126)), "short veg", AND(_xlpm.x>=200,_xlpm.x<=204), "wetland", OR(AND(_xlpm.x>=0,_xlpm.x<=4), AND(_xlpm.x>=100,_xlpm.x<=104)), "bare", AND(_xlpm.x>=205,_xlpm.x<=207), "water", _xlpm.x=241, "snow/ice" ) )} -> short veg | C12: {=_xlfn.LET(_xlpm.x, VLOOKUP($A12, scenarios!$A$2:$K$109, C$1, 0), _xlfn.IFS( _xlpm.x=250, "built up", _xlpm.x=244, "cropland", OR(AND(_xlpm.x>=27,_xlpm.x<=48), AND(_xlpm.x>=127,_xlpm.x<=148)), "tall veg", OR(AND(_xlpm.x>=5,_xlpm.x<=26), AND(_xlpm.x>=105,_xlpm.x<=126)), "short veg", AND(_xlpm.x>=200,_xlpm.x<=204), "wetland", OR(AND(_xlpm.x>=0,_xlpm.x<=4), AND(_xlpm.x>=100,_xlpm.x<=104)), "bare", AND(_xlpm.x>=205,_xlpm.x<=207), "water", _xlpm.x=241, "snow/ice" ) )} -> short veg | D12: {=_xlfn.LET(_xlpm.x, VLOOKUP($A12, scenarios!$A$2:$K$109, D$1, 0), _xlfn.IFS( _xlpm.x=250, "built up", _xlpm.x=244, "cropland", OR(AND(_xlpm.x>=27,_xlpm.x<=48), AND(_xlpm.x>=127,_xlpm.x<=148)), "tall veg", OR(AND(_xlpm.x>=5,_xlpm.x<=26), AND(_xlpm.x>=105,_xlpm.x<=126)), "short veg", AND(_xlpm.x>=200,_xlpm.x<=204), "wetland", OR(AND(_xlpm.x>=0,_xlpm.x<=4), AND(_xlpm.x>=100,_xlpm.x<=104)), "bare", AND(_xlpm.x>=205,_xlpm.x<=207), "water", _xlpm.x=241, "snow/ice" ) )} -> short veg | E12: {=_xlfn.LET(_xlpm.x, VLOOKUP($A12, scenarios!$A$2:$K$109, E$1, 0), _xlfn.IFS( _xlpm.x=250, "built up", _xlpm.x=244, "cropland", OR(AND(_xlpm.x>=27,_xlpm.x<=48), AND(_xlpm.x>=127,_xlpm.x<=148)), "tall veg", OR(AND(_xlpm.x>=5,_xlpm.x<=26), AND(_xlpm.x>=105,_xlpm.x<=126)), "short veg", AND(_xlpm.x>=200,_xlpm.x<=204), "wetland", OR(AND(_xlpm.x>=0,_xlpm.x<=4), AND(_xlpm.x>=100,_xlpm.x<=104)), "bare", AND(_xlpm.x>=205,_xlpm.x<=207), "water", _xlpm.x=241, "snow/ice" ) )} -> short veg | F12: {=_xlfn.LET(_xlpm.x, VLOOKUP($A12, scenarios!$A$2:$K$109, F$1, 0), _xlfn.IFS( _xlpm.x=250, "built up", _xlpm.x=244, "cropland", OR(AND(_xlpm.x>=27,_xlpm.x<=48), AND(_xlpm.x>=127,_xlpm.x<=148)), "tall veg", OR(AND(_xlpm.x>=5,_xlpm.x<=26), AND(_xlpm.x>=105,_xlpm.x<=126)), "short veg", AND(_xlpm.x>=200,_xlpm.x<=204), "wetland", OR(AND(_xlpm.x>=0,_xlpm.x<=4), AND(_xlpm.x>=100,_xlpm.x<=104)), "bare", AND(_xlpm.x>=205,_xlpm.x<=207), "water", _xlpm.x=241, "snow/ice" ) )} -> short veg | G12: {=_xlfn.LET(_xlpm.x, VLOOKUP($A12, scenarios!$A$2:$K$109, G$1, 0), _xlfn.IFS( _xlpm.x=250, "built up", _xlpm.x=244, "cropland", OR(AND(_xlpm.x>=27,_xlpm.x<=48), AND(_xlpm.x>=127,_xlpm.x<=148)), "tall veg", OR(AND(_xlpm.x>=5,_xlpm.x<=26), AND(_xlpm.x>=105,_xlpm.x<=126)), "short veg", AND(_xlpm.x>=200,_xlpm.x<=204), "wetland", OR(AND(_xlpm.x>=0,_xlpm.x<=4), AND(_xlpm.x>=100,_xlpm.x<=104)), "bare", AND(_xlpm.x>=205,_xlpm.x<=207), "water", _xlpm.x=241, "snow/ice" ) )} -> short veg | H12: {=_xlfn.LET(_xlpm.x, VLOOKUP($A12, scenarios!$A$2:$K$109, H$1, 0), _xlfn.IFS( _xlpm.x=250, "built up", _xlpm.x=244, "cropland", OR(AND(_xlpm.x>=27,_xlpm.x<=48), AND(_xlpm.x>=127,_xlpm.x<=148)), "tall veg", OR(AND(_xlpm.x>=5,_xlpm.x<=26), AND(_xlpm.x>=105,_xlpm.x<=126)), "short veg", AND(_xlpm.x>=200,_xlpm.x<=204), "wetland", OR(AND(_xlpm.x>=0,_xlpm.x<=4), AND(_xlpm.x>=100,_xlpm.x<=104)), "bare", AND(_xlpm.x>=205,_xlpm.x<=207), "water", _xlpm.x=241, "snow/ice" ) )} -> short veg | I12: {=_xlfn.LET(_xlpm.x, VLOOKUP($A12, scenarios!$A$2:$K$109, I$1, 0), _xlfn.IFS( _xlpm.x=250, "built up", _xlpm.x=244, "cropland", OR(AND(_xlpm.x>=27,_xlpm.x<=48), AND(_xlpm.x>=127,_xlpm.x<=148)), "tall veg", OR(AND(_xlpm.x>=5,_xlpm.x<=26), AND(_xlpm.x>=105,_xlpm.x<=126)), "short veg", AND(_xlpm.x>=200,_xlpm.x<=204), "wetland", OR(AND(_xlpm.x>=0,_xlpm.x<=4), AND(_xlpm.x>=100,_xlpm.x<=104)), "bare", AND(_xlpm.x>=205,_xlpm.x<=207), "water", _xlpm.x=241, "snow/ice" ) )} -> short veg | ... K12: {=_xlfn.LET(_xlpm.x, VLOOKUP($A12, scenarios!$A$2:$K$109, K$1, 0), _xlfn.IFS( _xlpm.x=250, "built up", _xlpm.x=244, "cropland", OR(AND(_xlpm.x>=27,_xlpm.x<=48), AND(_xlpm.x>=127,_xlpm.x<=148)), "tall veg", OR(AND(_xlpm.x>=5,_xlpm.x<=26), AND(_xlpm.x>=105,_xlpm.x<=126)), "short veg", AND(_xlpm.x>=200,_xlpm.x<=204), "wetland", OR(AND(_xlpm.x>=0,_xlpm.x<=4), AND(_xlpm.x>=100,_xlpm.x<=104)), "bare", AND(_xlpm.x>=205,_xlpm.x<=207), "water", _xlpm.x=241, "snow/ice" ) )} -> short veg | L12: {=IFERROR(_xlfn.SWITCH(VLOOKUP($A12, scenarios!$A$2:$P$109, L$1, 0), 1, "Permanent agriculture", 2, "Hard commodities", 3, "Shifting cultivation", 4, "Logging", 5, "Wildfire", 6, "Settlements & infrastructure", 7, "Other natural disturbances"), "")} -> Wildfire | M12: =_xlfn.LET(_xlpm.x, scenarios!M11, IF(OR(ISERROR(_xlpm.x), _xlpm.x=0), "", _xlpm.x)) -> 2015 | N12: =_xlfn.LET(_xlpm.x, scenarios!N11, IF(OR(ISERROR(_xlpm.x), _xlpm.x=0), "", _xlpm.x)) | O12: =_xlfn.LET(_xlpm.x, scenarios!O11, IF(OR(ISERROR(_xlpm.x), _xlpm.x=0), "", _xlpm.x)) | P12: =_xlfn.LET(_xlpm.x, scenarios!P11, IF(OR(ISERROR(_xlpm.x), _xlpm.x=0), "", _xlpm.x)) | Q12: =_xlfn.LET(_xlpm.x, scenarios!Q11, IF(OR(ISERROR(_xlpm.x), _xlpm.x=0), "", _xlpm.x)) | R12: =_xlfn.LET(_xlpm.x, scenarios!R11, IF(OR(ISERROR(_xlpm.x), _xlpm.x=0), "", _xlpm.x))
